Workbook
Name DATA: 'F&B'!$1:$1048606
Name ExternalData_1: 'Live Rate'!$A$1:$C$398

Sheet Cover D
A1: DEKWANEH | E1: =#REF! -> #REF! | F1: Cost > 40%
A2: =E1 -> #REF!
A3: ='Live Rate'!D2 -> 89,700 | B3: SP USD | C3: SP LBP | E3: Cost Price | F3: Cost % | G3: Net Profit | H3: Current Price | I3: Cost Price | J3: Profit | K3: Cost %
A4: Starters | H4: 0.1
A5: French Fries | B5: 6 | C5: =B5*90000 -> 540000 | D5: =E5/$A$2 -> #REF! | E5: =STARTERS!$C$10 -> #REF! | F5: =IF(E5="","",IF(ISBLANK(C5),"",E5/C5)) -> #REF! | G5: =C5-E5 -> #REF! | H5: =(C5*$H$4)+C5 -> 594000 | I5: =E5 -> #REF! | J5: =H5-I5 -> #REF! | K5: =I5/H5 -> #REF!
A6: Wedges | B6: 6.5 | C6: =B6*90000 -> 585000 | D6: =E6/$A$2 -> #REF! | E6: =STARTERS!$L$10 -> #REF! | F6: =IF(E6="","",IF(ISBLANK(C6),"",E6/C6)) -> #REF! | G6: =C6-E6 -> #REF! | H6: =(C6*$H$4)+C6 -> 643500 | I6: =E6 -> #REF! | J6: =H6-I6 -> #REF! | K6: =I6/H6 -> #REF!
A7: Baked Potato | B7: 5 | C7: =B7*90000 -> 450000 | D7: =E7/$A$2 -> #REF! | E7: =STARTERS!$C$54 -> #REF! | F7: =IF(E7="","",IF(ISBLANK(C7),"",E7/C7)) -> #REF! | G7: =C7-E7 -> #REF! | H7: =(C7*$H$4)+C7 -> 495000 | I7: =E7 -> #REF! | J7: =H7-I7 -> #REF! | K7: =I7/H7 -> #REF!
A8: Onion Rings | C8: =B8*90000 -> 0 | D8: =E8/$A$2 -> #REF! | E8: =STARTERS!$C$237 -> #REF! | F8: =IF(E8="","",IF(ISBLANK(C8),"",E8/C8)) -> #REF! | G8: =C8-E8 -> #REF! | H8: =(C8*$H$4)+C8 -> 0 | I8: =E8 -> #REF! | J8: =H8-I8 -> #REF! | K8: =I8/H8 -> #REF!
A9: Cheese Garlic | B9: 6 | C9: =B9*90000 -> 540000 | D9: =E9/$A$2 -> #REF! | E9: =STARTERS!$L$54 -> #REF! | F9: =IF(E9="","",IF(ISBLANK(C9),"",E9/C9)) -> #REF! | G9: =C9-E9 -> #REF! | H9: =(C9*$H$4)+C9 -> 594000 | I9: =E9 -> #REF! | J9: =H9-I9 -> #REF! | K9: =I9/H9 -> #REF!
A10: Classic Nachos | C10: =B10*90000 -> 0 | D10: =E10/$A$2 -> #REF! | E10: =STARTERS!$C$191 -> #REF! | F10: =IF(E10="","",IF(ISBLANK(C10),"",E10/C10)) -> #REF! | G10: =C10-E10 -> #REF! | H10: =(C10*$H$4)+C10 -> 0 | I10: =E10 -> #REF! | J10: =H10-I10 -> #REF! | K10: =I10/H10 -> #REF!
A11: Cheese Nachos | B11: 10 | C11: =B11*90000 -> 900000 | D11: =E11/$A$2 -> #REF! | E11: =STARTERS!$C$99 -> #REF! | F11: =IF(E11="","",IF(ISBLANK(C11),"",E11/C11)) -> #REF! | G11: =C11-E11 -> #REF! | H11: =(C11*$H$4)+C11 -> 990000 | I11: =E11 -> #REF! | J11: =H11-I11 -> #REF! | K11: =I11/H11 -> #REF!
A12: Chicken Wings | B12: 7.5 | C12: =B12*90000 -> 675000 | D12: =E12/$A$2 -> #REF! | E12: =STARTERS!$L$99 -> #REF! | F12: =IF(E12="","",IF(ISBLANK(C12),"",E12/C12)) -> #REF! | G12: =C12-E12 -> #REF! | H12: =(C12*$H$4)+C12 -> 742500 | I12: =E12 -> #REF! | J12: =H12-I12 -> #REF! | K12: =I12/H12 -> #REF!
A13: Chicken Nuggets | B13: 5 | C13: =B13*90000 -> 450000 | D13: =E13/$A$2 -> #REF! | E13: =STARTERS!$L$191 -> #REF! | F13: =IF(E13="","",IF(ISBLANK(C13),"",E13/C13)) -> #REF! | G13: =C13-E13 -> #REF! | H13: =(C13*$H$4)+C13 -> 495000 | I13: =E13 -> #REF! | J13: =H13-I13 -> #REF! | K13: =I13/H13 -> #REF!
A14: Pro's Combo | C14: =B14*90000 -> 0 | D14: =E14/$A$2 -> #REF! | E14: =STARTERS!$L$237 -> #REF! | F14: =IF(E14="","",IF(ISBLANK(C14),"",E14/C14)) -> #REF! | G14: =C14-E14 -> #REF! | H14: =(C14*$H$4)+C14 -> 0 | I14: =E14 -> #REF! | J14: =H14-I14 -> #REF! | K14: =I14/H14 -> #REF!
A15: Breaded Mozzarella | B15: 7.5 | C15: =B15*90000 -> 675000 | D15: =E15/$A$2 -> #REF! | E15: =STARTERS!$L$144 -> #REF! | F15: =IF(E15="","",IF(ISBLANK(C15),"",E15/C15)) -> #REF! | G15: =C15-E15 -> #REF! | H15: =(C15*$H$4)+C15 -> 742500 | I15: =E15 -> #REF! | J15: =H15-I15 -> #REF! | K15: =I15/H15 -> #REF!
A16: Quesadillas Chicken | B16: 7 | C16: =B16*90000 -> 630000 | D16: =E16/$A$2 -> #REF! | E16: =STARTERS!C284 -> #REF! | F16: =IF(E16="","",IF(ISBLANK(C16),"",E16/C16)) -> #REF! | G16: =C16-E16 -> #REF! | H16: =(C16*$H$4)+C16 -> 693000 | I16: =E16 -> #REF! | J16: =H16-I16 -> #REF! | K16: =I16/H16 -> #REF!
A17: Chicken Tenders | B17: 9 | C17: =B17*90000 -> 810000 | D17: =E17/$A$2 -> #REF! | E17: =STARTERS!C144 -> #REF! | F17: =IF(E17="","",IF(ISBLANK(C17),"",E17/C17)) -> #REF! | G17: =C17-E17 -> #REF! | H17: =(C17*$H$4)+C17 -> 891000 | I17: =E17 -> #REF! | J17: =H17-I17 -> #REF! | K17: =I17/H17 -> #REF!
A18: Salmon Delight | C18: =B18*90000 -> 0 | D18: =E18/$A$2 -> #REF! | E18: =STARTERS!L599 -> #REF! | F18: =IF(E18="","",IF(ISBLANK(C18),"",E18/C18)) -> #REF! | G18: =C18-E18 -> #REF! | H18: =(C18*$H$4)+C18 -> 0 | I18: =E18 -> #REF! | J18: =H18-I18 -> #REF! | K18: =I18/H18 -> #REF!
A19: =STARTERS!L640 -> Truffle Puttin | C19: =B19*90000 -> 0 | D19: =E19/$A$2 -> #REF! | E19: =STARTERS!L644 -> #REF! | F19: =IF(E19="","",IF(ISBLANK(C19),"",E19/C19)) -> #REF! | G19: =C19-E19 -> #REF! | H19: =(C19*$H$4)+C19 -> 0 | I19: =E19 -> #REF! | J19: =H19-I19 -> #REF! | K19: =I19/H19 -> #REF!
A20: Dynamite Shrimps | B20: 11 | C20: =B20*90000 -> 990000 | D20: =E20/$A$2 -> #REF! | E20: =STARTERS!$C$329 -> #REF! | F20: =IF(E20="","",IF(ISBLANK(C20),"",E20/C20)) -> #REF! | G20: =C20-E20 -> #REF! | H20: =(C20*$H$4)+C20 -> 1089000 | I20: =E20 -> #REF! | J20: =H20-I20 -> #REF! | K20: =I20/H20 -> #REF!
A21: Truffle Fries | B21: 9 | C21: =B21*90000 -> 810000 | D21: =E21/$A$2 -> #REF! | E21: =STARTERS!$L$329 -> 26242.167 | F21: =IF(E21="","",IF(ISBLANK(C21),"",E21/C21)) -> 0.032397738 | G21: =C21-E21 -> 783757.83 | H21: =(C21*$H$4)+C21 -> 891000 | I21: =E21 -> 26242.167 | J21: =H21-I21 -> 864757.83 | K21: =I21/H21 -> 0.029452489
A22: Dynamite Chicken | C22: =B22*90000 -> 0 | D22: =E22/$A$2 -> #REF! | E22: =STARTERS!$C$374 -> #REF! | F22: =IF(E22="","",IF(ISBLANK(C22),"",E22/C22)) -> #REF! | G22: =C22-E22 -> #REF! | H22: =(C22*$H$4)+C22 -> 0 | I22: =E22 -> #REF! | J22: =H22-I22 -> #REF! | K22: =I22/H22 -> #REF!
A23: Criss Cut Truffle | C23: =B23*90000 -> 0 | D23: =E23/$A$2 -> #REF! | E23: =STARTERS!$C$465 -> #REF! | H23: =(C23*$H$4)+C23 -> 0 | I23: =E23 -> #REF! | J23: =H23-I23 -> #REF! | K23: =I23/H23 -> #REF!
A24: Twiter Fries | B24: 8.5 | C24: =B24*90000 -> 765000 | D24: =E24/$A$2 -> #REF! | E24: =STARTERS!$L$374 -> #REF! | F24: =IF(E24="","",IF(ISBLANK(C24),"",E24/C24)) -> #REF! | G24: =C24-E24 -> #REF! | H24: =(C24*$H$4)+C24 -> 841500 | I24: =E24 -> #REF! | J24: =H24-I24 -> #REF! | K24: =I24/H24 -> #REF!
A25: Cheese Potato | C25: =B25*90000 -> 0 | D25: =E25/$A$2 -> #REF! | E25: =STARTERS!$C$420 -> #REF! | F25: =IF(E25="","",IF(ISBLANK(C25),"",E25/C25)) -> #REF! | G25: =C25-E25 -> #REF! | H25: =#REF!*$H$4+#REF! -> #REF! | I25: =#REF! -> #REF! | J25: =H25-I25 -> #REF! | K25: =IF(#REF!="","",IF(ISBLANK(H25),"",I25/H25)) -> #REF!
A26: HM Wedges Truffle | C26: =B26*90000 -> 0 | D26: =E26/$A$2 -> #REF! | E26: =STARTERS!$L$420 -> #REF! | F26: =IF(E26="","",IF(ISBLANK(C26),"",E26/C26)) -> #REF! | G26: =C26-E26 -> #REF! | H26: =#REF!*$H$4+#REF! -> #REF! | I26: =#REF! -> #REF! | J26: =H26-I26 -> #REF! | K26: =IF(#REF!="","",IF(ISBLANK(H26),"",I26/H26)) -> #REF!
A27: Fries Combo | C27: =B27*90000 -> 0 | D27: =E27/$A$2 -> #REF! | E27: =STARTERS!$C$510 -> #REF! | F27: =IF(E27="","",IF(ISBLANK(C27),"",E27/C27)) -> #REF! | G27: =C27-E27 -> #REF! | H27: =#REF!*$H$4+#REF! -> #REF! | I27: =#REF! -> #REF! | J27: =H27-I27 -> #REF! | K27: =IF(#REF!="","",IF(ISBLANK(H27),"",I27/H27)) -> #REF!
B28: 9 | C28: =B28*90000 -> 810000 | F28: =IF(E28="","",IF(ISBLANK(C28),"",E28/C28))
A29: Salads | F29: =IF(E29="","",IF(ISBLANK(C29),"",E29/C29))
A30: Rocket Parmesan | C30: =B30/90000 -> 0 | D30: =E30/$A$2 -> #REF! | E30: =SALADS!$C$10 -> #REF! | F30: =IF(E30="","",IF(ISBLANK(C30),"",E30/C30)) -> #REF! | G30: =C30-E30 -> #REF! | H30: =#REF!*$H$4+#REF! -> #REF! | I30: =#REF! -> #REF! | J30: =H30-I30 -> #REF! | K30: =IF(#REF!="","",IF(ISBLANK(H30),"",I30/H30)) -> #REF!
A31: Greek | B31: 8 | C31: =B31*90000 -> 720000 | D31: =E31/$A$2 -> #REF! | E31: =SALADS!$L$10 -> #REF! | F31: =IF(E31="","",IF(ISBLANK(C31),"",E31/C31)) -> #REF! | G31: =C31-E31 -> #REF! | H31: =(C31*$H$4)+C31 -> 792000 | I31: =E31 -> #REF! | J31: =H31-I31 -> #REF! | K31: =I31/H31 -> #REF!
A32: Caesar | B32: 8 | C32: =B32*90000 -> 720000 | D32: =E32/$A$2 -> #REF! | E32: =SALADS!$C$54 -> #REF! | F32: =IF(E32="","",IF(ISBLANK(C32),"",E32/C32)) -> #REF! | G32: =C32-E32 -> #REF! | H32: =(C32*$H$4)+C32 -> 792000 | I32: =E32 -> #REF! | J32: =H32-I32 -> #REF! | K32: =I32/H32 -> #REF!
A33: Chicken Caesar | B33: 11 | C33: =B33*90000 -> 990000 | D33: =E33/$A$2 -> #REF! | E33: =SALADS!$L$54 -> #REF! | F33: =IF(E33="","",IF(ISBLANK(C33),"",E33/C33)) -> #REF! | G33: =C33-E33 -> #REF! | H33: =(C33*$H$4)+C33 -> 1089000 | I33: =E33 -> #REF! | J33: =H33-I33 -> #REF! | K33: =I33/H33 -> #REF!
A34: Pasta Tuna | B34: 9 | C34: =B34*90000 -> 810000 | D34: =E34/$A$2 -> #REF! | E34: =SALADS!$C$99 -> #REF! | F34: =IF(E34="","",IF(ISBLANK(C34),"",E34/C34)) -> #REF! | G34: =C34-E34 -> #REF! | H34: =(C34*$H$4)+C34 -> 891000 | I34: =E34 -> #REF! | J34: =H34-I34 -> #REF! | K34: =I34/H34 -> #REF!
A35: Freekeh Halloumi Salad | C35: =B35*90000 -> 0 | D35: =E35/$A$2 -> #REF! | E35: =SALADS!L373 -> #REF! | F35: =IF(E35="","",IF(ISBLANK(C35),"",E35/C35)) -> #REF! | G35: =C35-E35 -> #REF! | H35: =(C35*$H$4)+C35 -> 0 | I35: =E35 -> #REF! | J35: =H35-I35 -> #REF! | K35: =I35/H35 -> #REF!
A36: Pro's | C36: =B36*90000 -> 0 | D36: =E36/$A$2 -> #REF! | E36: =SALADS!$C$146 -> #REF! | F36: =IF(E36="","",IF(ISBLANK(C36),"",E36/C36)) -> #REF! | G36: =C36-E36 -> #REF! | H36: =(C36*$H$4)+C36 -> 0 | I36: =E36 -> #REF! | J36: =H36-I36 -> #REF! | K36: =I36/H36 -> #REF!
A37: Crab Avocado | B37: 10 | C37: =B37*90000 -> 900000 | D37: =E37/$A$2 -> #REF! | E37: =SALADS!$L$282 -> #REF! | F37: =IF(E37="","",IF(ISBLANK(C37),"",E37/C37)) -> #REF! | G37: =C37-E37 -> #REF! | H37: =(C37*$H$4)+C37 -> 990000 | I37: =E37 -> #REF! | J37: =H37-I37 -> #REF! | K37: =I37/H37 -> #REF!
A38: Kale Chicken | B38: 10 | C38: =B38*90000 -> 900000 | D38: =E38/$A$2 -> #REF! | E38: =SALADS!C192 -> #REF! | F38: =IF(E38="","",IF(ISBLANK(C38),"",E38/C38)) -> #REF! | G38: =C38-E38 -> #REF! | H38: =(C38*$H$4)+C38 -> 990000 | I38: =E38 -> #REF! | J38: =H38-I38 -> #REF! | K38: =I38/H38 -> #REF!
A39: Cranberry Citrus Crunch | C39: =B39*90000 -> 0 | D39: =E39/$A$2 -> #REF! | E39: =SALADS!L463 -> #REF! | F39: =IF(E39="","",IF(ISBLANK(C39),"",E39/C39)) -> #REF! | G39: =C39-E39 -> #REF! | H39: =(C39*$H$4)+C39 -> 0 | I39: =E39 -> #REF! | J39: =H39-I39 -> #REF! | K39: =I39/H39 -> #REF!
A40: BBQ Chicken Salad | B40: 10 | C40: =B40*90000 -> 900000 | D40: =E40/$A$2 -> #REF! | E40: =SALADS!$L$237 -> #REF! | F40: =IF(E40="","",IF(ISBLANK(C40),"",E40/C40)) -> #REF! | G40: =C40-E40 -> #REF! | H40: =(C40*$H$4)+C40 -> 990000 | I40: =E40 -> #REF! | J40: =H40-I40 -> #REF! | K40: =I40/H40 -> #REF!
...

Sheet F&B
B1: Item | C1: Unit | D1: Qty | E1: Unit Price $ | F1: Unit Price LBP | G1: Total Price | H1: Supplier | I1: Brand
B2: Food
B3: BAKERY
B4: ARABIC BREAD | C4: BAG | E4: 0.97 | F4: =E4*9000 -> 8730 | G4: =D4*F4 -> 0 | H4: WOODEN BAKERY | I4: WOODEN BAKERY
B5: BAGUETTE 24CM 40 PCS | C5: BOX | E5: 25.22 | F5: =E5*9000 -> 226980 | G5: =D5*F5 -> 0 | H5: Delifrance | I5: Delifrance
B6: BAGUETTE BROWN 40 PCS | C6: BOX | E6: =27.93*1.1 -> 30.723 | F6: =E6*9000 -> 276507 | G6: =D6*F6 -> 0 | H6: Delifrance | I6: Delifrance
B7: BREAD CRUMBS YELLOW 25 KG | C7: BAG | E7: 2 | F7: =E7*9000 -> 18000 | G7: =D7*F7 -> 0 | H7: Aya Foods
B8: PANCO CRUMBS 10 KG | C8: Bag | E8: =4.5*1.1 -> 4.95 | F8: =E8*9000 -> 44550 | G8: =D8*F8 -> 0 | H8: E. JABRA
B9: KAAK CRUSHED WHITE KG | C9: KG | E9: 2.22 | F9: =E9*9000 -> 19980 | G9: =D9*F9 -> 0 | H9: WOODEN BAKERY | I9: WOODEN BAKERY
B10: BURGER BUN 6 PCS | C10: Bag | E10: =(31.18*1.1)/(54/6) -> 3.8108889 | F10: =E10*9000 -> 34298 | G10: =D10*F10 -> 0 | H10: Delifrance | I10: Delifrance
B11: SOURDOUGH BAGUETTE W 50 PCS 28 CM | C11: BOX | E11: =27.45*1.1 -> 30.195 | F11: =E11*9000 -> 271755 | G11: =D11*F11 -> 0 | H11: Delifrance | I11: Delifrance
B12: SOURDOUGH BAGUETTE B 50 PCS 28 CM | C12: BOX | E12: =31.67*1.1 -> 34.837 | F12: =E12*9000 -> 313533 | G12: =D12*F12 -> 0 | H12: Delifrance | I12: Delifrance
B13: BURGER BUN BROWN 6 PCS | C13: Bag | E13: 3.7 | F13: =E13*9000 -> 33300 | G13: =D13*F13 -> 0 | H13: Delifrance | I13: Delifrance
B14: MINI BURGER BUN 12 PCS | C14: Bag | E14: =2.11*1.1 -> 2.321 | F14: =E14*9000 -> 20889 | G14: =D14*F14 -> 0 | H14: Delifrance | I14: Delifrance
B15: CIABATTA PCS 40 PCS | C15: Box | E15: =1.1*21.4 -> 23.54 | F15: =E15*9000 -> 211860 | G15: =D15*F15 -> 0 | H15: Delifrance | I15: Delifrance
B16: CIABATTA BROWN 40 PCS | C16: Box | E16: 53 | F16: =E16*9000 -> 477000 | G16: =D16*F16 -> 0 | H16: Delifrance | I16: Delifrance
B17: FLOUR EXTRA (50KG) | C17: Bag | E17: 29.42 | F17: =E17*9000 -> 264780 | G17: =D17*F17 -> 0 | H17: PC FOOD | I17: Taj
B18: FLOUR T65 (25KG) | C18: Bag | E18: 19 | F18: =E18*9000 -> 171000 | G18: =D18*F18 -> 0 | H18: BAKALIAN | I18: T65
B19: CAPUTO FLOUR 5 KG | C19: Bag | E19: 22 | F19: =E19*9000 -> 198000 | G19: =D19*F19 -> 0 | H19: Interal | I19: Farina
B20: YEAST FRESH 0.5 KG | C20: PCS | E20: =2.25*1.1 -> 2.475 | F20: =E20*9000 -> 22275 | G20: =D20*F20 -> 0 | H20: AYA FOODS
B21: CHEESE ROLLS DOUGH | C21: PACK | E21: 1.5 | F21: =E21*9000 -> 13500 | G21: =D21*F21 -> 0 | H21: TONYS FOOD | I21: TONYS FOOD
B22: PAIN DE MIE 12mm FRAIS | C22: Loaf | E22: =(14.49/2)*1.1 -> 7.9695 | F22: =E22*9000 -> 71725.5 | G22: =D22*F22 -> 0 | H22: Delifrance | I22: Delifrance
B23: PAIN DE MIE 12mm | C23: Loaf | E23: =1.1*7.59 -> 8.349 | F23: =E23*9000 -> 75141 | G23: =D23*F23 -> 0 | H23: Delifrance
B24: PAIN CAMPAGNE RUSTIQUE (4x650GRSx18S) | C24: Loaf | E24: =13.8*1.1 -> 15.18 | F24: =E24*9000 -> 136620 | G24: =D24*F24 -> 0 | H24: Delifrance
B25: PAIN AU LAIT FRAIS 12 PCS | C25: Loaf | E25: =2.1*1.1 -> 2.31 | F25: =E25*9000 -> 20790 | G25: =D25*F25 -> 0 | H25: Delifrance
B26: PUFF PASTRY KG 12*400G | C26: BOX | E26: =25*1.1 -> 27.5 | F26: =E26*9000 -> 247500 | G26: =D26*F26 -> 0 | H26: PLEIN SOLIEL | I26: PLEIN SOLIEL
B27: SUBMARINE BUN 5 PCS | C27: BAG | E27: 3.3 | F27: =E27*9000 -> 29700 | G27: =D27*F27 -> 0 | H27: Delifrance | I27: Delifrance
B28: TORTILLA 6" CORN 12 KG | C28: Box | E28: 65 | F28: =E28*9000 -> 585000 | G28: =D28*F28 -> 0 | H28: POMO | I28: POMO
B29: TORTILLA 6" FLOUR 12 KG | C29: Box | E29: 65 | F29: =E29*9000 -> 585000 | G29: =D29*F29 -> 0 | H29: POMO | I29: POMO
B30: TORTILLA 12" FLOUR 12 KG | C30: Box | E30: 60 | F30: =E30*9000 -> 540000 | G30: =D30*F30 -> 0 | H30: POMO | I30: POMO
B31: CANNED | F31: =E31*9000 -> 0
B32: ANCHOIX 80 GR KG | C32: PCS | E32: =3.75*1.1 -> 4.125 | F32: =E32*9000 -> 37125 | G32: =F32*D32 -> 0 | H32: GENERAL PROMOTION | I32: Robo
B33: CORN FLOWER 340 gr | C33: PCS | E33: 2.5 | F33: =E33*9000 -> 22500 | G33: =F33*D33 -> 0 | H33: PC FOODS | I33: DOMO
B34: ARTICHAUT 390 GR | C34: PCS | E34: 4.2 | F34: =E34*9000 -> 37800 | G34: =F34*D34 -> 0
B35: CHEDDAR DIP KG (3.01KG) | C35: PCS | E35: =11*1.1 -> 12.1 | F35: =E35*9000 -> 108900 | G35: =F35*D35 -> 0 | H35: AYA FOODS
B36: CAPERS KG 950 GRS | C36: Box | E36: =9.5*1.1 -> 10.45 | F36: =E36*9000 -> 94050 | G36: =F36*D36 -> 0 | H36: GENERAL PROMOTION | I36: MARLY
B37: DEMI GLASS (0.925 KG) | C37: PCS | E37: =26*1.1 -> 28.6 | F37: =E37*9000 -> 257400 | G37: =F37*D37 -> 0 | H37: AYA FOODS | I37: KNORR
B38: CONDENSED MILK KG (395GR) | C38: PCS | E38: 0.98 | F38: =E38*9000 -> 8820 | G38: =F38*D38 -> 0 | H38: PC FOODS | I38: Nestle
B39: PEANUT BUTTER 340 GRS | C39: PCS | E39: =1.3*1.1 -> 1.43 | F39: =E39*9000 -> 12870 | G39: =F39*D39 -> 0 | H39: GENERAL PROMOTION | I39: PNUT
B40: JALAPENOS KG (2KG) | C40: PCS | E40: =6.5*1.1 -> 7.15 | F40: =E40*9000 -> 64350 | G40: =F40*D40 -> 0 | H40: AYA FOODS
...

Sheet SAUCES
A1: Caesar Sauce | B1: 8.6 | C1: KG | D1: =D15/B1 -> 75709.953 | E1: =D1/90000 -> 0.8412217 | I1: Lemon Mustard | J1: 9.12 | K1: KG | L1: =L15/J1 -> 13999.178 | M1: =L1/90000 -> 0.15554642
A2: Name | B2: Qty | C2: Unit Price | D2: Total Cost | I2: Name | J2: Qty | K2: Unit Price | L2: Total Cost
A3: Anchoix | B3: 2 | C3: ='F&B'!$F$32 -> 37125 | D3: =B3*C3 -> 74250 | I3: Djion Mustard | J3: 1.25 | K3: =$C$9 -> 51480 | L3: =J3*K3 -> 64350
A4: Mayonnaise | B4: 4 | C4: ='F&B'!$F$250 -> 108900 | D4: =B4*C4 -> 435600 | I4: Sunflower Oil | J4: 5 | K4: ='F&B'!$F$57/18 -> 8250 | L4: =J4*K4 -> 41250
A5: Fresh Cream | B5: 1 | C5: ='F&B'!$F$87 -> 58500 | D5: =B5*C5 -> 58500 | I5: Salt | J5: 0.1 | K5: =$C$11 -> 58500 | L5: =J5*K5 -> 5850
A6: Parmesan Cheese | B6: 0.2 | C6: ='F&B'!$F$103 -> 148500 | D6: =B6*C6 -> 29700
A7: Garlic | B7: 0.2 | C7: ='F&B'!$F$292 -> 19800 | D7: =B7*C7 -> 3960 | I7: Lemon Juice | J7: 1.25 | K7: ='F&B'!$F$287*1.5 -> 12150 | L7: =J7*K7 -> 15187.5
A8: Worchester Sauce | B8: 0.2 | C8: ='F&B'!$F$260/3.8 -> 41684.211 | D8: =B8*C8 -> 8336.8421 | I8: Water | J8: 1.5 | L8: =J8*K8 -> 0
A9: Mustard Dijon | B9: 0.25 | C9: ='F&B'!$F$247/5 -> 51480 | D9: =B9*C9 -> 12870 | I9: Black Pepper | J9: 0.02 | K9: =C12 -> 51750 | L9: =J9*K9 -> 1035
A10: Milk | B10: 0.5 | C10: ='F&B'!$F$96 -> 13050 | D10: =B10*C10 -> 6525
A11: Salt | B11: 0.25 | C11: ='F&B'!$F$143 -> 58500 | D11: =B11*C11 -> 14625
A12: Black Pepper | B12: 0.005 | C12: ='F&B'!$F$148 -> 51750 | D12: =B12*C12 -> 258.75
A13: Lemon Juice | B13: 0.4 | C13: ='F&B'!F287*2 -> 16200 | D13: =B13*C13 -> 6480
D14: =B14*C14 -> 0
A15: TOTAL | D15: =SUM(D3:D14) -> 651105.59 | I15: TOTAL | L15: =IF(SUM(L3:L14)=0,"",SUM(L3:L14)) -> 127672.5
A16: Selling Price 45 Grs | B16: =IF(D16="","",IF(ISBLANK(C16),"",D16/C16)) -> 0.11748096 | C16: 29000 | D16: =D1*0.045 -> 3406.9479 | I16: Selling Price 45 Grs | J16: =IF(L16="","",IF(ISBLANK(K16),"",L16/K16)) -> 0.028634682 | K16: 22000 | L16: =L1*0.045 -> 629.96299
A20: Cocktail Sauce | B20: 4.7 | C20: KG | D20: =D33/B20 -> 26573.761 | E20: =D20/90000 -> 0.29526401 | I20: Garlic Dip | J20: 1.2 | K20: KG | L20: =L33/J20 -> 10676.625
A21: Name | B21: Qty | C21: Unit Price | D21: Total Cost | I21: Name | J21: Qty | K21: Unit Price | L21: Total Cost
A22: Mayonnaise | B22: 1 | C22: =$C$4 -> 108900 | D22: =B22*C22 -> 108900 | I22: Garlic | J22: 0.1 | K22: =$C$7 -> 19800 | L22: =J22*K22 -> 1980
A23: Ketchup | B23: 0.5 | C23: ='F&B'!$F$249/13 -> 3946.1538 | D23: =B23*C23 -> 1973.0769 | I23: Egg | J23: 1 | K23: ='F&B'!$F$84/30 -> 1299 | L23: =J23*K23 -> 1299
A24: Salt | B24: 0.007 | C24: =C11 -> 58500 | D24: =B24*C24 -> 409.5 | I24: Salt | J24: 0.001 | K24: =C11 -> 58500 | L24: =J24*K24 -> 58.5
A25: White Pepper | B25: 0.001 | C25: ='F&B'!$F$172 -> 89820 | D25: =B25*C25 -> 89.82 | I25: Sunflower Oil | J25: 1 | K25: =$K$4 -> 8250 | L25: =J25*K25 -> 8250
A26: Tabasco | B26: 0.006 | C26: ='F&B'!$F$253 -> 24750 | D26: =B26*C26 -> 148.5 | I26: Lemon Juice | J26: 0.075 | K26: =$K$7 -> 12150 | L26: =J26*K26 -> 911.25
A27: Worcestershire Sauce | B27: 0.025 | C27: =C8 -> 41684.211 | D27: =B27*C27 -> 1042.1053 | I27: Lamoud Layoun | J27: 0.04 | K27: ='F&B'!$F$161 -> 7830 | L27: =J27*K27 -> 313.2
A28: Water | B28: 0.1 | D28: =B28*C28 -> 0
A29: Lousiana Wings Sauce | B29: 0.12 | C29: ='F&B'!$F$258/3.75 -> 55440 | D29: =B29*C29 -> 6652.8
A30: Junal | B30: 0.08 | C30: ='F&B'!$F$41 -> 14850 | D30: =B30*C30 -> 1188
A31: BBQ | B31: 0.08 | C31: ='F&B'!$F$246/3.79 -> 56160.95 | D31: =B31*C31 -> 4492.876
A32: American Mustard | B32: 0.1
A33: TOTAL | D33: =IF(SUM(D22:D32)=0,"",SUM(D22:D32)) -> 124896.68 | I33: TOTAL | L33: =IF(SUM(L22:L32)=0,"",SUM(L22:L32)) -> 12811.95
A34: Selling Price 45 Grs | B34: =IF(D34="","",IF(ISBLANK(C34),"",D34/C34)) -> 0.04783277 | C34: 25000 | D34: =D20*0.045 -> 1195.8193 | I34: Selling Price 45 Grs | J34: =IF(L34="","",IF(ISBLANK(K34),"",L34/K34)) -> 0.032029875 | K34: 15000 | L34: =L20*0.045 -> 480.44813
A36: Balsamic Sauce | B36: 0.826 | C36: KG | D36: =D45/B36 -> 21446.564 | E36: =D36/90000 -> 0.23829515 | I36: Garnish
A37: Name | B37: Qty | C37: Unit Price | D37: Total Cost | I37: Name | J37: Qty | K37: Unit Price | L37: Total Cost
A38: Dijon Mustard | B38: 0.04 | C38: =K3 -> 51480 | D38: =B38*C38 -> 2059.2 | I38: Pickles | J38: 0.002 | K38: ='F&B'!$F$49 -> 135000 | L38: =J38*K38 -> 270
A39: Sunflower Oil | B39: 0.215 | C39: =K25 -> 8250 | D39: =B39*C39 -> 1773.75 | I39: Lolo Lettuce | J39: 0.01 | K39: ='F&B'!F297 -> 16650 | L39: =J39*K39 -> 166.5
A40: Balsamic Vinegar | B40: 0.13 | C40: ='F&B'!$F$255/5 -> 35640 | D40: =B40*C40 -> 4633.2 | I40: Tomato | J40: 0.06 | K40: ='F&B'!$F$279 -> 7200 | L40: =J40*K40 -> 432
A41: Olive Oil | B41: 0.24 | C41: ='F&B'!$F$43/13 -> 38076.923 | D41: =B41*C41 -> 9138.4615 | I41: Onion | J41: 0.02 | K41: ='F&B'!$F$290 -> 6300 | L41: =J41*K41 -> 126
A42: Salt | B42: 0.001 | C42: =K24 -> 58500 | D42: =B42*C42 -> 58.5
A43: Black Pepper | B43: 0.001 | C43: =K9 -> 51750 | D43: =B43*C43 -> 51.75
A44: Water | B44: 0.2
...

Sheet UTL COST
A1: UTILITY AND PREP. COST | C1: =#REF! -> #REF! | E1: Gas Count
A2: DEKWANEH | D2: Total Cost | E2: 10 KG | F2: Qty | G2: 35 KG | H2: Qty | I2: Total
A3: Shorenting Oil | B3: ='F&B'!$F$54 -> 369000 | C3: 0.0075 | D3: =B3*C3 -> 2767.5
A4: Gas | B4: =$I$4*($C$1) -> #REF! | C4: 7000 | D4: =B4/C4 -> #REF! | E4: 13 | F4: 10 | G4: 38 | H4: 30 | I4: =E4*F4+G4*H4 -> 1270
A5: Electricity | B5: =3260*C1 -> #REF! | C5: 45000 | D5: =B5/C5 -> #REF!
A6: Wood | B6: =180*C1 -> #REF! | C6: =350+175 -> 525 | D6: =B6/C6 -> #REF!
A7: Gas Pizza | B7: =I7*$C$1 -> #REF! | C7: 450 | D7: =B7/C7 -> #REF! | G7: 35 | H7: 4 | I7: =G7*H7 -> 140
A8: TOTAL | D8: =IF(SUM(D3:D6)=0,"",SUM(D3:D6)) -> #REF!
A9: Labor Cost | B9: 180000000 | C9: 22000 | D9: =B9/C9 -> 8181.8182

Sheet Prep
A1: Croutons | B1: 4 | C1: KG | D1: =D13/B1 -> 0 | G1: Sambousik | H1: 115 | I1: PCS | J1: =J13/H1 -> 1482.0651 | K1: =J1/#REF! -> #REF!
A2: Name | B2: Qty | C2: Unit Price | D2: Total Cost | G2: Name | H2: Qty | I2: Unit Price | J2: Total Cost
G3: Dough | H3: 1.5 | I3: =SAUCES!D82 -> 6006.1538 | J3: =I3*H3 -> 9009.2308
G4: Minced Beef | H4: 1.5 | I4: ='F&B'!F209 -> 99000 | J4: =I4*H4 -> 148500
G5: Onions | H5: 1.5 | I5: ='F&B'!F290 -> 6300 | J5: =I5*H5 -> 9450
G6: Label Cost | H6: =H1 -> 115 | I6: 400000 | J6: =I6/H6 -> 3478.2609
G7: Frying Oil | H7: 0.25 | I7: =C6 | J7: =H7*I7 -> 0
A13: TOTAL | D13: =IF(SUM(D3:D12)=0,"",SUM(D3:D12)) | G13: TOTAL | J13: =IF(SUM(J3:J12)=0,"",SUM(J3:J12)) -> 170437.49
A14: Selling Price 45 Grs | B14: =IF(D14="","",IF(ISBLANK(C14),"",D14/C14)) -> 0 | C14: 22000 | D14: =D1*0.045 -> 0 | G14: Selling Price 45 Grs | H14: =IF(J14="","",IF(ISBLANK(I14),"",J14/I14)) -> 0.0030314969 | I14: 22000 | J14: =J1*0.045 -> 66.692932
A17: Kibbeh Krass | B17: 240 | C17: PCS | D17: =D29/B17 -> 2246.7023 | E17: =D17/#REF! -> #REF! | G17: Cheese Rolls | H17: 115 | I17: PCS | J17: =J29/H17 -> 3103.3055 | K17: =J17/#REF! -> #REF!
A18: Name | B18: Qty | C18: Unit Price | D18: Total Cost | G18: Name | H18: Qty | I18: Unit Price | J18: Total Cost
A19: Minced Beef | B19: 5 | C19: =$I$4 -> 99000 | D19: =B19*C19 -> 495000 | G19: Akawi | H19: 0.6 | I19: ='F&B'!$F$82 -> 63000 | J19: =I19*H19 -> 37800
A20: Borghol | B20: 2.5 | C20: ='F&B'!F126 -> 11700 | D20: =B20*C20 -> 29250 | G20: Mozzarella | H20: 2 | I20: ='F&B'!$F$99/6 -> 126000 | J20: =I20*H20 -> 252000
A21: Onions | B21: 2 | C21: =$I$5 -> 6300 | D21: =B21*C21 -> 12600 | G21: Fetta | H21: 0.2 | I21: ='F&B'!$F$86 -> 44550 | J21: =I21*H21 -> 8910
A22: Label Cost | B22: =B17 -> 240 | C22: 400000 | D22: =C22/B22 -> 1666.6667 | G22: Rakaket Dough | H22: 4 | I22: ='F&B'!$F$21 -> 13500 | J22: =I22*H22 -> 54000
A23: Frying Oil | B23: 0.25 | C23: ='UTL COST'!D3 -> 2767.5 | D23: =B23*C23 -> 691.875 | G23: Label Cost | H23: =H17 -> 115 | I23: 400000 | J23: =I23/H23 -> 3478.2609
G24: Frying Oil | H24: 0.25 | I24: =C23 -> 2767.5 | J24: =H24*I24 -> 691.875
A29: TOTAL | D29: =IF(SUM(D19:D28)=0,"",SUM(D19:D28)) -> 539208.54 | G29: TOTAL | J29: =IF(SUM(J19:J28)=0,"",SUM(J19:J28)) -> 356880.14
A30: Selling Price 45 Grs | B30: =IF(D30="","",IF(ISBLANK(C30),"",D30/C30)) -> 0.0045955273 | C30: 22000 | D30: =D17*0.045 -> 101.1016 | G30: Selling Price 45 Grs | H30: =IF(J30="","",IF(ISBLANK(I30),"",J30/I30)) -> 0.0063476704 | I30: 22000 | J30: =J17*0.045 -> 139.64875
A32: Cheese Cake | B32: 8 | C32: PCS | D32: =D44/B32 -> 12991.335 | E32: =D32/#REF! -> #REF! | G32: Lahme Baajin | H32: 4.08 | I32: PCS | J32: =J44/H32 -> 30194.118
A33: Name | B33: Qty | C33: Unit Price | D33: Total Cost | G33: Name | H33: Qty | I33: Unit Price | J33: Total Cost
A34: Cream Cheese | B34: 0.55 | C34: ='F&B'!$F$101/8 -> 117450 | D34: =B34*C34 -> 64597.5 | G34: Minced Beef | H34: 1 | I34: ='F&B'!$F$209 -> 99000 | J34: =I34*H34 -> 99000
A35: Eggs | B35: 4 | C35: ='F&B'!$F$84/30 -> 1299 | D35: =B35*C35 -> 5196 | G35: Tomatoes | H35: 2 | I35: ='F&B'!$F$279 -> 7200 | J35: =I35*H35 -> 14400
A36: Sugar | B36: 0.3 | C36: ='F&B'!F145/50 -> 165.6 | D36: =B36*C36 -> 49.68 | G36: Onions | H36: 1 | I36: ='F&B'!$F$290 -> 6300 | J36: =I36*H36 -> 6300
A37: Cream Fresh | B37: 0.3 | C37: ='F&B'!$F$87 -> 58500 | D37: =B37*C37 -> 17550 | G37: Black Pepper | H37: 0.02 | I37: ='F&B'!$F$148 -> 51750 | J37: =I37*H37 -> 1035
A38: Vanilla Powder | B38: 0.05 | C38: ='F&B'!$F$178 -> 330750 | D38: =B38*C38 -> 16537.5 | G38: Debis El Roman | H38: 0.04 | I38: ='F&B'!$F$245 -> 32175 | J38: =I38*H38 -> 1287
G39: Salt | H39: 0.02 | I39: ='F&B'!$F$143 -> 58500 | J39: =I39*H39 -> 1170
A44: TOTAL | D44: =IF(SUM(D34:D43)=0,"",SUM(D34:D43)) -> 103930.68 | G44: TOTAL | J44: =IF(SUM(J34:J43)=0,"",SUM(J34:J43)) -> 123192
B45: =IF(D45="","",IF(ISBLANK(C45),"",D45/C45)) | G45: Selling Price 45 Grs | H45: =IF(J45="","",IF(ISBLANK(I45),"",J45/I45)) -> 0.061760695 | I45: 22000 | J45: =J32*0.045 -> 1358.7353
A48: Vine Leaves Ready | B48: 215 | C48: Grs | D48: =B48*C50/1000 -> 59985 | G48: Ajenet Knefe | H48: 14 | I48: PCS | J48: =J60/H48 -> #REF!
A49: Name | B49: Qty | C49: Unit Price | D49: Total Cost | G49: Name | H49: Qty | I49: Unit Price | J49: Total Cost
A50: Vine Leaves | B50: 4.06 | C50: 279000 | D50: =B50*C50 -> 1132740 | G50: Smid 1200kg | H50: 1.2 | I50: =1.3*#REF! -> #REF! | J50: =H50*I50 -> #REF! | K50: =J50/$J$60 -> #REF!
G51: Thin ferkha 160g | H51: 0.16 | I51: ='F&B'!$F$17/25 -> 10591.2 | J51: =H51*I51 -> 1694.592 | K51: =J51/$J$60 -> #REF!
G52: White sugar 400g | H52: 0.4 | I52: ='F&B'!$F$145/50 -> 165.6 | J52: =H52*I52 -> 66.24 | K52: =J52/$J$60 -> #REF!
G53: Misca 2 pcs | H53: 2 | I53: =0.02*#REF! -> #REF! | J53: =H53*I53 -> #REF! | K53: =J53/$J$60 -> #REF!
G54: Milk 3 liter | H54: 3 | I54: ='F&B'!$F$96 -> 13050 | J54: =H54*I54 -> 39150 | K54: =J54/$J$60 -> #REF!
G55: May zaher 50g | H55: 0.05 | I55: =0.4*#REF! -> #REF! | J55: =H55*I55 -> #REF! | K55: =J55/$J$60 -> #REF!
G56: May wared 30g | H56: 0.03 | I56: =0.4*#REF! -> #REF! | J56: =H56*I56 -> #REF! | K56: =J56/$J$60 -> #REF!
G57: Butter 400g | H57: 0.4 | I57: ='F&B'!$F$79/25 -> 14040 | J57: =H57*I57 -> 5616 | K57: =J57/$J$60 -> #REF!
A60: TOTAL | D60: =IF(SUM(D50:D59)=0,"",SUM(D50:D59)) -> 1132740 | G60: TOTAL | J60: =IF(SUM(J50:J59)=0,"",SUM(J50:J59)) -> #REF!
...

Sheet COMBOS
A1: COMBO DEALS FOR 2 - 3 - 4 - Family
A2: For 2
B3: Selling P | C3: Cost P | D3: Combo P | H3: NO FRIES | I3: Pepsi | J3: Water B
A4: Baked Potato | B4: 2.5 | C4: =#REF! -> #REF! | H4: =50000/90000 -> 0.55555556 | I4: =50000/90000 -> 0.55555556 | J4: 0.35
A5: Caesar Salad | B5: 7.5 | C5: =#REF! -> #REF!
A6: Light Chicken sand | B6: 10.5 | C6: =#REF! -> #REF!
A7: SOFT x2 | B7: 3.6 | C7: =I4*2 -> 1.1111111
A8: -0.09 | B8: 24.1 | C8: 5.47 | D8: 22
B9: 0.23 | C9: -2.1 | D9: =C8/D8 -> 0.24863636
A11: For 2 | G11: For 2
B12: Selling P | C12: Cost P | D12: Combo P | H12: Selling P | I12: Cost P | J12: Combo P
A13: Half Fries | B13: 2.5 | C13: =#REF!/2 -> #REF! | G13: Half Fries | H13: 2.5 | I13: =C13 -> #REF!
A14: Tangy B | B14: 13.5 | C14: =#REF!-H4 -> #REF! | D14: No Fries | G14: Pepp. Piz | H14: 11 | I14: =#REF! -> #REF!
A15: CHICK SUB | B15: 10 | C15: =#REF!-H4 -> #REF! | D15: No Fries | G15: Caesar Salad | H15: 7.5 | I15: =C5 -> #REF!
A16: Garlic Ch Br | B16: 4 | C16: =#REF! -> #REF! | G16: Garlic Ch Br | H16: 4 | I16: =C16 -> #REF!
A17: SOFT x2 | B17: 3.6 | C17: =I4*2 -> 1.1111111 | G17: SOFT x2 | H17: 3.6 | I17: =I4*2 -> 1.1111111
A18: -0.35 | B18: 33.6 | C18: 9.38 | D18: 25 | G18: -0.23 | H18: 28.6 | I18: 7.63 | J18: 22
B19: 0.28 | C19: -11.6 | D19: =C18/D18 -> 0.3752 | H19: 0.27 | I19: -6.6 | J19: =I18/J18 -> 0.34681818
A22: For 3 | G22: For 3
B23: Selling P | C23: Cost P | D23: Combo P | H23: Selling P | I23: Cost P | J23: Combo P
A24: 2 Half Fries | B24: 3.5 | C24: =#REF! -> #REF! | G24: 2 Half Fries | H24: 3.5 | I24: =C24 -> #REF!
A25: SWISS BURG | B25: 11.5 | C25: =#REF!-H4 -> #REF! | D25: No Fries | G25: Pep. Pizza | H25: 11 | I25: =I14 -> #REF!
A26: CHICK SUB | B26: 10 | C26: =C15 -> #REF! | D26: No Fries | G26: CHICK SUB | H26: 10 | I26: =C26 -> #REF! | J26: No Fries
A27: SOFT x3 | B27: 5.4 | C27: =I4*3 -> 1.6666667 | G27: SOFT x3 | H27: 5.4 | I27: =I4*3 -> 1.6666667
A28: Faj. Sand | B28: 11.5 | C28: =#REF!-H4 -> #REF! | D28: No Fries | G28: Caesar Salad | H28: 7.5 | I28: =C5 -> #REF!
A29: -0.21 | B29: 41.9 | C29: 11.34 | D29: 33 | G29: -0.12 | H29: 37.4 | I29: 10.31 | J29: 33
B30: 0.27 | C30: -8.9 | D30: =C29/D29 -> 0.34363636 | H30: 0.28 | I30: -4.4 | J30: =I29/J29 -> 0.31242424
A33: For 4 | G33: For 4
B34: Selling P | C34: Cost P | D34: Combo P | H34: Selling P | I34: Cost P | J34: Combo P
A35: COMBO | B35: 17 | C35: =#REF!/2.5 -> #REF! | D35: HALF | G35: COMBO | H35: 17 | I35: =C35 -> #REF! | J35: HALF
A36: Tangy B | B36: 13.5 | C36: =C14 -> #REF! | D36: No Fries | G36: Caesar Salad | H36: 7.5 | I36: =I28 -> #REF!
A37: CLASSIC B | B37: 8.5 | C37: =#REF!-H4 -> #REF! | D37: No Fries | G37: Tag. Pasta | H37: 11.5 | I37: =#REF! -> #REF!
A38: CHICK SUB | B38: 10 | C38: =C15 -> #REF! | D38: No Fries | G38: Reg. Pizza | H38: 11 | I38: =#REF! -> #REF!
A39: SOFT x4 | B39: 7.2 | C39: =I4*4 -> 2.2222222 | G39: SOFT x4 | H39: 7.2 | I39: =I4*4 -> 2.2222222
A40: Faj. Sand | B40: 11.5 | C40: =C28 -> #REF! | D40: No Fries | G40: Pepp. Piz | H40: 11 | I40: =I25 -> #REF!
A41: -0.35 | B41: 67.7 | C41: 16.78 | D41: 44 | G41: -0.33 | H41: 65.2 | I41: 17.64 | J41: 44
B42: 0.25 | C42: -23.7 | D42: =C41/D41 -> 0.38136364 | H42: 0.27 | I42: -21.2 | J42: =I41/J41 -> 0.40090909
A45: FAMILY | G45: FAMILY
B46: Selling P | C46: Cost P | D46: Combo P | H46: Selling P | I46: Cost P | J46: Combo P
A47: Half Fries | B47: 2.5 | C47: =C13 -> #REF! | G47: Half Fries | H47: 2.5 | I47: =C13 -> #REF!
...

Sheet BAR
A1: Items | B1: USD / Box | C1: =#REF! -> #REF! | D1: Price / Box | E1: Qty / Box | F1: Unit Price | G1: Elec. Cost | H1: Extra | I1: Unit Price | J1: Selling Price | K1: > 30 % | P1: =#REF! -> #REF!
A2: Water Big | B2: =3.3*1.1 -> 3.63 | C2: =B2*$C$1 -> #REF! | D2: =77*1515 -> 116655 | E2: 12 | F2: =(C2/E2)/$C$1 -> #REF! | G2: ='UTL COST'!$D$5/$C$1 -> #REF! | I2: =F2+G2+H2 -> #REF! | J2: 1.25 | K2: =I2/J2 -> #REF! | L2: =30*B2 -> 108.9 | N2: Latte | P2: =Q2/$P$1 -> #REF! | Q2: =Q4+Q5 -> #REF!
A3: Water Small | B3: =3.3*1.1 -> 3.63 | C3: =B3*$C$1 -> #REF! | D3: =77*1515 -> 116655 | E3: 24 | F3: =(C3/E3)/$C$1 -> #REF! | G3: ='UTL COST'!$D$5/$C$1 -> #REF! | I3: =F3+G3+H3 -> #REF! | J3: 0.75 | K3: =I3/J3 -> #REF! | L3: =20*B3 -> 72.6 | O3: Qty | P3: Unit Price | Q3: Total
A4: Soft Drinks | B4: =4.75*1.1 -> 5.225 | C4: =B4*$C$1 -> #REF! | D4: 178000 | E4: 12 | F4: =(C4/E4)/$C$1 -> #REF! | G4: ='UTL COST'!$D$5/$C$1 -> #REF! | I4: =F4+G4+H4 -> #REF! | J4: 1.25 | K4: =I4/J4 -> #REF! | L4: =B4*30 -> 156.75 | N4: Espresso | O4: 1 | P4: =$F$12 -> #REF! | Q4: =P4*O4 -> #REF!
A5: Engery Drinks | B5: 8 | C5: =B5*$C$1 -> #REF! | D5: 580000 | E5: 24 | F5: =(C5/E5)/$C$1 -> #REF! | G5: ='UTL COST'!$D$5/$C$1 -> #REF! | I5: =F5+G5+H5 -> #REF! | J5: 1.5 | K5: =I5/J5 -> #REF! | L5: =B5*2 -> 16 | N5: Milk | O5: 0.375 | P5: ='F&B'!$F$96 -> 13050 | Q5: =P5*O5 -> 4893.75
A6: Nescafe | B6: 4.01 | C6: =B6*$C$1 -> #REF! | D6: 250000 | E6: 35 | F6: =(C6/E6)/$C$1 -> #REF! | G6: ='UTL COST'!$D$5/$C$1 -> #REF! | I6: =F6+G6+H6 -> #REF! | J6: 1 | K6: =I6/J6 -> #REF! | L6: =B6*10 -> 40.1
A7: Tea | B7: 3.03 | C7: =B7*$C$1 -> #REF! | D7: 115000 | E7: 100 | F7: =(C7/E7)/$C$1 -> #REF! | G7: ='UTL COST'!$D$5/$C$1 -> #REF! | I7: =F7+G7+H7 -> #REF! | J7: 1 | K7: =I7/J7 -> #REF! | L7: =B7*2 -> 6.06
A8: Mix Tea | B8: 1.58 | C8: =B8*$C$1 -> #REF! | D8: 60000 | E8: 20 | F8: =(C8/E8)/$C$1 -> #REF! | G8: ='UTL COST'!$D$5/$C$1 -> #REF! | I8: =F8+G8+H8 -> #REF! | J8: 1 | K8: =I8/J8 -> #REF! | L8: =B8*2 -> 3.16 | N8: Mocha | P8: =Q8/$P$1 -> #REF! | Q8: =Q10+Q12+Q11 -> #REF!
A9: Latte | B9: =D9/38000 -> 0 | C9: - | D9: 0 | E9: 0 | F9: =$Q$2/$C$1 -> #REF! | G9: ='UTL COST'!$D$5/$C$1 -> #REF! | I9: =F9+G9+H9 -> #REF! | J9: 1.5 | K9: =I9/J9 -> #REF! | L9: =B9*2 -> 0 | O9: Qty | P9: Unit Price | Q9: Total
A10: Mocha | B10: =D10/38000 -> 0 | C10: - | D10: 0 | E10: 0 | F10: =$Q$8/$C$1 -> #REF! | G10: ='UTL COST'!$D$5/$C$1 -> #REF! | I10: =F10+G10+H10 -> #REF! | J10: 2 | K10: =I10/J10 -> #REF! | L10: =B10*2 -> 0 | N10: Espresso | O10: 1 | P10: =$F$12 -> #REF! | Q10: =P10*O10 -> #REF!
A11: Hot Chocolate | B11: =D11/38000 -> 0 | C11: - | D11: 0 | E11: 0 | F11: =$Q$14/$C$1 -> #REF! | G11: ='UTL COST'!$D$5/$C$1 -> #REF! | I11: =F11+G11+H11 -> #REF! | J11: 1.75 | K11: =I11/J11 -> #REF! | L11: =B11*2 -> 0 | N11: Chocolate Syrup | O11: 0.03 | P11: ='F&B'!$F$111/1.2 -> 56250 | Q11: =P11*O11 -> 1687.5
A12: Espresso | B12: 12 | C12: =B12*$C$1 -> #REF! | D12: 480000 | E12: 70 | F12: =(C12/E12)/$C$1 -> #REF! | G12: ='UTL COST'!$D$5/$C$1 -> #REF! | I12: =F12+G12+H12 -> #REF! | J12: 0.75 | K12: =I12/J12 -> #REF! | L12: =B12*5 -> 60 | N12: Milk | O12: 0.375 | P12: ='F&B'!$F$96 -> 13050 | Q12: =P12*O12 -> 4893.75
A13: Turkish Coffee | B13: 8.42 | C13: =B13*$C$1 -> #REF! | D13: 320000 | E13: 100 | F13: =(C13/E13)/$C$1 -> #REF! | G13: ='UTL COST'!$D$5/$C$1 -> #REF! | I13: =F13+G13+H13 -> #REF! | J13: 0.75 | K13: =I13/J13 -> #REF! | L13: =B13*2 -> 16.84
A14: Almaza | B14: =17.5*1.1 -> 19.25 | C14: =B14*$C$1 -> #REF! | D14: 640000 | E14: 24 | F14: =(C14/E14)/$C$1 -> #REF! | G14: ='UTL COST'!$D$5/$C$1 -> #REF! | H14: =$B$18 -> 0.18 | I14: =F14+G14+H14 -> #REF! | J14: 2 | K14: =I14/J14 -> #REF! | L14: =B14*3 -> 57.75 | N14: Hot Chocolate | P14: =Q14/P1 -> #REF! | Q14: =Q16+Q18+Q17 -> #REF!
A15: Perrier | B15: =17.01*1.1 -> 18.711 | C15: =B15*$C$1 -> #REF! | D15: 590000 | E15: 24 | F15: =(C15/E15)/$C$1 -> #REF! | G15: ='UTL COST'!$D$5/$C$1 -> #REF! | I15: =F15+G15+H15 -> #REF! | J15: 2 | K15: =I15/J15 -> #REF! | L15: =B15*2 -> 37.422 | O15: Qty | P15: Unit Price | Q15: Total
A16: Laziza | B16: 12.63 | C16: =B16*$C$1 -> #REF! | D16: 480000 | E16: 24 | F16: =(C16/E16)/$C$1 -> #REF! | G16: ='UTL COST'!$D$5/$C$1 -> #REF! | H16: =$B$18 -> 0.18 | I16: =F16+G16+H16 -> #REF! | J16: 2 | K16: =I16/J16 -> #REF! | L16: =B16*0.5 -> 6.315 | N16: Chocolate Powder | O16: 0.02 | P16: =(15.9*1.1)*C1 -> #REF! | Q16: =P16*O16 -> #REF!
A17: Iced Tea | B17: =3.07*4*1.1 -> 13.508 | C17: =B17*$C$1 -> #REF! | D17: 440000 | E17: 24 | F17: =(C17/E17)/$C$1 -> #REF! | G17: ='UTL COST'!$D$5/$C$1 -> #REF! | I17: =F17+G17+H17 -> #REF! | J17: 1.5 | K17: =I17/J17 -> #REF! | L17: =B17*2 -> 27.016 | N17: Chocolate Syrup | O17: 0.03 | P17: ='F&B'!$F$111/1.2 -> 56250 | Q17: =P17*O17 -> 1687.5
A18: Nuts | B18: 0.18 | C18: =B18*$C$1 -> #REF! | D18: 7000 | E18: 1 | F18: =(C18/E18)/$C$1 -> #REF! | G18: ='UTL COST'!$D$5/$C$1 -> #REF! | I18: =F18+G18+H18 -> #REF! | J18: 0.75 | K18: =I18/J18 -> #REF! | L18: =B18*100 -> 18 | N18: Milk | O18: 0.375 | P18: ='F&B'!$F$96 -> 13050 | Q18: =P18*O18 -> 4893.75
A19: 1 Syrup Cocktail | C19: - | F19: =Q20/$C$1 -> #REF! | G19: ='UTL COST'!$D$5/$C$1 -> #REF! | I19: =F19+G19+H19 -> #REF! | J19: 2 | K19: =I19/J19 -> #REF! | L19: =B19*2 -> 0
A20: 2 Syrup Cocktail | C20: - | F20: =Q26/$C$1 -> #REF! | G20: ='UTL COST'!$D$5/$C$1 -> #REF! | I20: =F20+G20+H20 -> #REF! | J20: 2 | K20: =I20/J20 -> #REF! | L20: =B20*2 -> 0 | N20: Cocktail 1 Syrup | P20: =Q20/$P$1 -> #REF! | Q20: =Q22+Q23+Q24 -> #REF!
A21: Perrier Large | B21: =19.49*1.1 -> 21.439 | C21: =B21*$C$1 -> #REF! | D21: 590000 | E21: 12 | F21: =(C21/E21)/$C$1 -> #REF! | G21: ='UTL COST'!$D$5/$C$1 -> #REF! | I21: =F21+G21+H21 -> #REF! | J21: 5 | K21: =I21/J21 -> #REF! | L21: =B21*1 -> 21.439 | O21: Qty | P21: Unit Price | Q21: Total
A22: Almaza KEG | B22: 33 | C22: =B22*$C$1 -> #REF! | D22: 590000 | E22: 55 | F22: =(C22/E22)/$C$1 -> #REF! | G22: ='UTL COST'!$D$5/$C$1 -> #REF! | I22: =F22+G22+H22 -> #REF! | J22: 2 | K22: =I22/J22 -> #REF! | L22: =B22*1 -> 33 | N22: Syrup 1883 | O22: 0.02 | P22: =7.6*1.1*($P$1) -> #REF! | Q22: =P22*O22 -> #REF!
N23: Juice 1 | O23: 0.06 | P23: 170000 | Q23: =P23*O23 -> 10200
N24: Juice 2 | O24: 0.06 | P24: =$P$23 -> 170000 | Q24: =P24*O24 -> 10200
N26: Cocktail 2 Syrups | P26: =Q26/$P$1 -> #REF! | Q26: =Q28+Q29+Q30+Q31 -> #REF!
O27: Qty | P27: Unit Price | Q27: Total
N28: Syrup 1883 | O28: 0.02 | P28: =P22 -> #REF! | Q28: =P28*O28 -> #REF!
N29: Juice 1 | O29: 0.06 | P29: =$P$23 -> 170000 | Q29: =P29*O29 -> 10200
N30: Juice 2 | O30: 0.06 | P30: =$P$23 -> 170000 | Q30: =P30*O30 -> 10200
N31: Syrup 1883 | O31: 0.02 | P31: =P28 -> #REF! | Q31: =P31*O31 -> #REF!

Sheet KIDS MENU
A1: KIDS MENU
I4: DISH NAME | J4: Chicken Tenders
B5: DISH NAME | C5: French Fries Side
I6: EST. SALE PPRICE | J6: 120000
B7: EST. SALE PPRICE | C7: =3.5*100000 -> 350000
I8: TOTAL COST | J8: =IF(SUM(L20,L35,L43)=0,"",SUM(L20,L35,L43)) -> #REF! | L8: =J8/90000 -> #REF!
B9: TOTAL COST | C9: =IF(SUM(E21,E36,E44)=0,"",SUM(E21,E36,E44)) -> #REF! | E9: =C9/90000 -> #REF!
I10: COST MARGIN | J10: =IF(J8="","",IF(ISBLANK(J6),"",J8/J6)) -> #REF!
B11: COST MARGIN | C11: =IF(C9="","",IF(ISBLANK(C7),"",C9/C7)) -> #REF!
I12: NET PROFIT | J12: =J6-J8 -> #REF!
B13: NET PROFIT | C13: =C7-C9 -> #REF!
I15: PRIMARY INGREDIENTS
B16: PRIMARY INGREDIENTS | I16: Product Name | J16: Qty. | K16: Cost (per unit) | L16: Total Cost
B17: Product Name | C17: Qty. | D17: Cost (per unit) | E17: Total Cost | I17: Chicken Breast | J17: 0.2 | K17: ='F&B'!$F$229 -> 81000 | L17: =IF(OR(ISBLANK(J17),ISBLANK(K17)),"",K17*J17) -> 16200
B18: French Fries | C18: 0.2 | D18: ='F&B'!$F$68/10 -> 19665 | E18: =IF(OR(ISBLANK(C18),ISBLANK(D18)),"",D18*C18) -> 3933
I19: Ketchup | J19: 0.05 | K19: ='F&B'!F249/4 -> 12825 | L19: =IF(OR(ISBLANK(J19),ISBLANK(K19)),"",K19*J19) -> 641.25
E20: =IF(OR(ISBLANK(C20),ISBLANK(D20)),"",D20*C20) | I20: TOTAL | L20: =IF(SUM(L17:L19)=0,"",SUM(L17:L19)) -> 16841.25
B21: TOTAL | E21: =IF(SUM(E18:E20)=0,"",SUM(E18:E20)) -> 3933
I22: SECONDARY INGREDIENTS
B23: SECONDARY INGREDIENTS | I23: Product Name | J23: Qty | K23: Cost | L23: Total Cost
B24: Product Name | C24: Qty | D24: Cost | E24: Total Cost
I25: Breaded | J25: 2 | K25: =SAUCES!D48 -> 563.76 | L25: =K25*J25 -> 1127.52
E26: =D26*C26 -> 0
E27: =D27*C27 -> 0
E28: =D28*C28 -> 0
E29: =D29*C29 -> 0
E30: =D30*C30 -> 0
E31: =D31*C31 -> 0
E32: =D32*C32 -> 0
E33: =D33*C33 -> 0
E34: =D34*C34 -> 0
E35: =D35*C35 -> 0 | I35: TOTAL | L35: =SUM(L25:L34) -> 1127.52
B36: TOTAL | E36: =IF(SUM(E26:E35)=0,"",SUM(E26:E35))
I37: UTILITY AND PREP. COST
B38: UTILITY AND PREP. COST | I38: Name | L38: Total Cost
B39: Name | E39: Total Cost | I39: Shorenting Oil | J39: ='UTL COST'!$B$3 -> 369000 | K39: ='UTL COST'!$C$3 -> 0.0075 | L39: ='UTL COST'!$D$3 -> 2767.5
B40: Shorenting Oil | C40: ='UTL COST'!$B$3 -> 369000 | D40: ='UTL COST'!$C$3 -> 0.0075 | E40: ='UTL COST'!$D$3 -> 2767.5 | I40: Gas | J40: ='UTL COST'!$B$4 -> #REF! | K40: ='UTL COST'!$C$4 -> 7000 | L40: ='UTL COST'!$D$4 -> #REF!
B41: Gas | C41: ='UTL COST'!$B$4 -> #REF! | D41: ='UTL COST'!$C$4 -> 7000 | E41: ='UTL COST'!$D$4 -> #REF! | I41: Electricity | J41: ='UTL COST'!$B$5 -> #REF! | K41: ='UTL COST'!$C$5 -> 45000 | L41: ='UTL COST'!$D$5 -> #REF!
B42: Electricity | C42: ='UTL COST'!$B$5 -> #REF! | D42: ='UTL COST'!$C$5 -> 45000 | E42: ='UTL COST'!$D$5 -> #REF! | I42: Water | J42: ='UTL COST'!$B$6 -> #REF! | K42: ='UTL COST'!$C$6 -> 525 | L42: 0.1
B43: Water | C43: ='UTL COST'!$B$6 -> #REF! | D43: ='UTL COST'!$C$6 -> 525 | E43: 0.1 | I43: TOTAL | L43: =IF(SUM(L39:L42)=0,"",SUM(L39:L42)) -> #REF!
...

Sheet BIRTHDAYS
A1: 19
A2: Birthdays Formula | B2: Qty | C2: Cost Price | D2: Total | F2: Qty | G2: SP | I2: Mini Sandwiches | J2: Qty | K2: UP | L2: Total
A3: Greek Salad - 8 Prs | B3: 8 | C3: =#REF! -> #REF! | D3: =B3*C3 -> #REF! | F3: 1 | G3: =D3*F3 -> #REF! | I3: Turkey | J3: 0.12 | K3: ='F&B'!$E$223 -> 15.88 | L3: =J3*K3 -> 1.9056
A4: Chicken Ceasar Salad - 8 Prs | B4: 8 | C4: =#REF! -> #REF! | D4: =B4*C4 -> #REF! | F4: 1 | G4: =D4*F4 -> #REF! | I4: Chicken | J4: =0.16*10 -> 1.6 | K4: ='F&B'!$E$229 -> 9 | L4: =J4*K4 -> 14.4
A5: Chicken Tenders - Pcs | B5: 50 | C5: =#REF!/4 -> #REF! | D5: =B5*C5 -> #REF! | F5: 50 | G5: =D5*F5 -> #REF! | I5: Emmental | J5: 0.12 | K5: ='F&B'!$E$85 -> 14.35 | L5: =J5*K5 -> 1.722
A6: Mini Sandwiches - Pcs | B6: 50 | C6: =L10 -> #REF! | D6: =B6*C6 -> #REF! | E6: =L11 -> #REF! | F6: 50 | G6: =F6*E6 -> #REF! | I6: Bread | J6: 40 | K6: =1.45/6 -> 0.24166667 | L6: =J6*K6 -> 9.6666667
A7: Nuggets - Pcs | C7: =#REF!/5 -> #REF! | D7: =B7*C7 -> #REF! | E7: 0.7 | F7: 50 | G7: =F7*E7 -> 35 | I7: Iceberg | J7: 0.75 | K7: ='F&B'!$E$277 -> 1.5 | L7: =J7*K7 -> 1.125
A8: Mini Burgers - Pcs | B8: 75 | C8: =M29 -> #REF! | D8: =B8*C8 -> #REF! | E8: 2.25 | F8: 50 | G8: =D8*F8 -> #REF! | I8: Honey Mustard | J8: 0.2 | K8: =SAUCES!$D$122/#REF! -> #REF! | L8: =J8*K8 -> #REF!
A9: Fries | B9: 6 | C9: =#REF! -> #REF! | D9: =B9*C9 -> #REF! | F9: 8 | G9: =D9*F9 -> #REF! | K9: 40 | L9: =SUM(L3:L8) -> #REF!
A10: Pizza Mini - Pcs | B10: 50 | C10: =#REF!/9 -> #REF! | D10: =B10*C10 -> #REF! | E10: 0.8 | F10: 50 | G10: =E10*F10 -> 40 | L10: =L9/K9 -> #REF!
D11: =SUM(D3:D10) -> #REF! | G11: =SUM(G3:G10) -> #REF! | L11: =L10*3 -> #REF!
A12: Penne Pasta | B12: 8 | C12: =#REF! -> #REF! | D12: =B12*C12 -> #REF!
A13: Tag. Pasta | B13: 8 | C13: =#REF! -> #REF! | D13: =B13*C13 -> #REF!
A14: Drinks | B14: 10 | C14: =200000/89000 -> 2.247191 | D14: =B14*C14 -> 22.47191
A15: Hommos | B15: 8 | C15: =#REF! -> #REF! | D15: =B15*C15 -> #REF!
A16: Water Big | B16: 15 | C16: 0.26 | D16: =B16*C16 -> 3.9
D17: =SUM(D11:D16) -> #REF!
B18: =18*50 -> 900 | D18: =D17/B18 -> #REF!
J22: Mini Burgers | K22: Qty | L22: UP | M22: Total
E23: 250 | F23: 310 | G23: 390 | J23: Burger Patty 80 Grs | K23: 1 | L23: 0.8 | M23: =K23*L23 -> 0.8
E24: 25-30 | F24: 30-35 | G24: 35-40 | J24: Burger Bun | K24: 1 | L24: =2.1/12 -> 0.175 | M24: =K24*L24 -> 0.175
J25: Ketchup | K25: 0.002 | L25: ='F&B'!F249/#REF! -> #REF! | M25: =K25*L25 -> #REF!
L29: 1 | M29: =SUM(M23:M28) -> #REF!
M30: =M29/L29 -> #REF! | N30: =M30+0.13+0.5 -> #REF!
M31: =M30*2 -> #REF!

Sheet RICE MEALS
A1: RICE MEALS FOOD COST
B6: DISH NAME | C6: White Rice | J6: DISH NAME | K6: Green Salad
B8: EST. SALE PPRICE | J8: EST. SALE PPRICE
E9: 18 Portions
B10: TOTAL COST | C10: =IF(SUM(E22,E37,E45)=0,"",SUM(E22,E37,E45)) -> #REF! | E10: =C10/18 -> #REF! | J10: TOTAL COST | K10: =IF(SUM(M22,M37,M45)=0,"",SUM(M22,M37,M45)) -> 7515.063
B12: COST MARGIN | C12: =IF(C10="","",IF(ISBLANK(C8),"",C10/C8)) -> #REF! | J12: COST MARGIN | K12: =IF(K10="","",IF(ISBLANK(K8),"",K10/K8))
B14: NET PROFIT | C14: =C8-C10 -> #REF! | J14: NET PROFIT | K14: =K8-K10 -> -7515.063
B17: PRIMARY INGREDIENTS | J17: PRIMARY INGREDIENTS
B18: Product Name | C18: Qty. | D18: Cost (per unit) | E18: Total Cost | J18: Product Name | K18: Qty. | L18: Cost (per unit) | M18: Total Cost
B19: Rice | C19: 1.08 | D19: ='F&B'!F141/20 -> 12150 | E19: =IF(OR(ISBLANK(C19),ISBLANK(D19)),"",D19*C19) -> 13122 | J19: Iceberg | K19: 0.2 | L19: ='F&B'!F277 -> 13500 | M19: =IF(OR(ISBLANK(K19),ISBLANK(L19)),"",L19*K19) -> 2700
B20: Magi Cubes | C20: 1 | D20: ='F&B'!F42/12 -> 2062.5 | E20: =IF(OR(ISBLANK(C20),ISBLANK(D20)),"",D20*C20) -> 2062.5 | J20: Red Cabbage | K20: 0.15 | L20: ='F&B'!F294 -> 6750 | M20: =IF(OR(ISBLANK(K20),ISBLANK(L20)),"",L20*K20) -> 1012.5
B21: Sunflower Oil | C21: 0.02 | D21: ='F&B'!F57/8 -> 18562.5 | E21: =IF(OR(ISBLANK(C21),ISBLANK(D21)),"",D21*C21) -> 371.25 | J21: Carrots | K21: 0.15 | L21: ='F&B'!F293 -> 6750 | M21: =IF(OR(ISBLANK(K21),ISBLANK(L21)),"",L21*K21) -> 1012.5
B22: TOTAL | E22: =IF(SUM(E19:E21)=0,"",SUM(E19:E21)) -> 15555.75 | J22: TOTAL | M22: =IF(SUM(M19:M21)=0,"",SUM(M19:M21)) -> 4725
B24: SECONDARY INGREDIENTS | J24: SECONDARY INGREDIENTS
B25: Product Name | C25: Qty | D25: Cost | E25: Total Cost | J25: Product Name | K25: Qty | L25: Cost | M25: Total Cost
B27: Butter | C27: 0.015 | D27: ='F&B'!F79/25 -> 14040 | E27: =D27*C27 -> 210.6 | J27: Argula | K27: 0.2 | L27: ='F&B'!F302 -> 10800 | M27: =L27*K27 -> 2160
B28: Salt | C28: 0.03 | D28: ='F&B'!F143/25 -> 2340 | E28: =D28*C28 -> 70.2 | J28: Sauce | K28: 1 | L28: =SAUCES!L16 -> 629.96299 | M28: =L28*K28 -> 629.96299
B29: Black Pepper | C29: 0.005 | D29: ='F&B'!F148 -> 51750 | E29: =D29*C29 -> 258.75 | M29: =L29*K29 -> 0
B30: Bay leaves | C30: 1 | D30: ='F&B'!F153/50 -> 540 | E30: =D30*C30 -> 540 | M30: =L30*K30 -> 0
E31: =D31*C31 -> 0 | M31: =L31*K31 -> 0
E32: =D32*C32 -> 0 | M32: =L32*K32 -> 0
E33: =D33*C33 -> 0 | M33: =L33*K33 -> 0
E34: =D34*C34 -> 0 | M34: =L34*K34 -> 0
E35: =D35*C35 -> 0 | M35: =L35*K35 -> 0
E36: =D36*C36 -> 0 | M36: =L36*K36 -> 0
B37: TOTAL | E37: =IF(SUM(E27:E36)=0,"",SUM(E27:E36)) -> 1079.55 | J37: TOTAL | M37: =IF(SUM(M27:M36)=0,"",SUM(M27:M36)) -> 2789.963
B39: UTILITY AND PREP. COST | J39: UTILITY AND PREP. COST
B40: Name | E40: Total Cost | J40: Name | M40: Total Cost
B41: Shorenting Oil | C41: ='UTL COST'!$B$3 -> 369000 | D41: ='UTL COST'!$C$3 -> 0.0075 | E41: 0 | J41: Shorenting Oil | K41: ='UTL COST'!$B$3 -> 369000 | L41: ='UTL COST'!$C$3 -> 0.0075 | M41: 0
B42: Gas | C42: ='UTL COST'!$B$4 -> #REF! | D42: ='UTL COST'!$C$4 -> 7000 | E42: ='UTL COST'!$D$4 -> #REF! | J42: Gas | K42: ='UTL COST'!$B$4 -> #REF! | L42: ='UTL COST'!$C$4 -> 7000 | M42: 0
B43: Electricity | C43: ='UTL COST'!$B$5 -> #REF! | D43: ='UTL COST'!$C$5 -> 45000 | E43: 0 | J43: Electricity | K43: ='UTL COST'!$B$5 -> #REF! | L43: ='UTL COST'!$C$5 -> 45000 | M43: 0
B44: Water | C44: ='UTL COST'!$B$6 -> #REF! | D44: ='UTL COST'!$C$6 -> 525 | E44: 0.1 | J44: Water | K44: ='UTL COST'!$B$6 -> #REF! | L44: ='UTL COST'!$C$6 -> 525 | M44: 0.1
B45: TOTAL | E45: =IF(SUM(E41:E44)=0,"",SUM(E41:E44)) -> #REF! | J45: TOTAL | M45: =IF(SUM(M41:M44)=0,"",SUM(M41:M44)) -> 0.1
B51: DISH NAME | C51: Chicken & CHicken | J51: DISH NAME | K51: Meat and Rice
B53: EST. SALE PPRICE | C53: 11 | J53: EST. SALE PPRICE | K53: 12
B55: TOTAL COST | C55: =IF(SUM(E67,E82,E90)=0,"",SUM(E67,E82,E90)) -> #REF! | J55: TOTAL COST | K55: =IF(SUM(M67,M82,M90)=0,"",SUM(M67,M82,M90)) -> #REF! | M55: =K55/90000 -> #REF!
B57: COST MARGIN | C57: =IF(C55="","",IF(ISBLANK(C53),"",C55/C53)) -> #REF! | J57: COST MARGIN | K57: =IF(K55="","",IF(ISBLANK(K53),"",K55/K53)) -> #REF!
B59: NET PROFIT | C59: =C53-C55 -> #REF! | J59: NET PROFIT | K59: =K53-K55 -> #REF!
B62: PRIMARY INGREDIENTS | J62: PRIMARY INGREDIENTS
B63: Product Name | C63: Qty. | D63: Cost (per unit) | E63: Total Cost | J63: Product Name | K63: Qty. | L63: Cost (per unit) | M63: Total Cost
...

Sheet STARTERS
A1: STARTERS FOOD COST
B6: DISH NAME | C6: French Fries Large | K6: DISH NAME | L6: Wedges
B8: EST. SALE PPRICE | C8: =3.5*100000 -> 350000 | K8: EST. SALE PPRICE | L8: 70000
B10: TOTAL COST | C10: =IF(SUM(E22,E37,E45)=0,"",SUM(E22,E37,E45)) -> #REF! | E10: =C10/90000 -> #REF! | K10: TOTAL COST | L10: =IF(SUM(N22,N37,N45)=0,"",SUM(N22,N37,N45)) -> #REF!
B12: COST MARGIN | C12: =IF(C10="","",IF(ISBLANK(C8),"",C10/C8)) -> #REF! | K12: COST MARGIN | L12: =IF(L10="","",IF(ISBLANK(L8),"",L10/L8)) -> #REF!
B14: NET PROFIT | C14: =C8-C10 -> #REF! | K14: NET PROFIT | L14: =L8-L10 -> #REF!
B17: PRIMARY INGREDIENTS | K17: PRIMARY INGREDIENTS
B18: Product Name | C18: Qty. | D18: Cost (per unit) | E18: Total Cost | K18: Product Name | L18: Qty. | M18: Cost (per unit) | N18: Total Cost
B19: French Fries | C19: 0.4 | D19: ='F&B'!$F$68/10 -> 19665 | E19: =IF(OR(ISBLANK(C19),ISBLANK(D19)),"",D19*C19) -> 7866 | K19: French Fries | L19: 0.4 | M19: =D19 -> 19665 | N19: =IF(OR(ISBLANK(L19),ISBLANK(M19)),"",M19*L19) -> 7866
E21: =IF(OR(ISBLANK(C21),ISBLANK(D21)),"",D21*C21) | N21: =IF(OR(ISBLANK(L21),ISBLANK(M21)),"",M21*L21)
B22: TOTAL | E22: =IF(SUM(E19:E21)=0,"",SUM(E19:E21)) -> 7866 | K22: TOTAL | N22: =IF(SUM(N19:N21)=0,"",SUM(N19:N21)) -> 7866
B24: SECONDARY INGREDIENTS | K24: SECONDARY INGREDIENTS
B25: Product Name | C25: Qty | D25: Cost | E25: Total Cost | K25: Product Name | L25: Qty | M25: Cost | N25: Total Cost
E27: =D27*C27 -> 0 | K27: BBq Sauce | L27: 0.05 | M27: ='F&B'!$F$246/3.79 -> 56160.95 | N27: =M27*L27 -> 2808.0475
E28: =D28*C28 -> 0 | N28: =M28*L28 -> 0
E29: =D29*C29 -> 0 | N29: =M29*L29 -> 0
E30: =D30*C30 -> 0 | N30: =M30*L30 -> 0
E31: =D31*C31 -> 0 | N31: =M31*L31 -> 0
E32: =D32*C32 -> 0 | N32: =M32*L32 -> 0
E33: =D33*C33 -> 0 | N33: =M33*L33 -> 0
E34: =D34*C34 -> 0 | N34: =M34*L34 -> 0
E35: =D35*C35 -> 0 | N35: =M35*L35 -> 0
E36: =D36*C36 -> 0 | N36: =M36*L36 -> 0
B37: TOTAL | E37: =IF(SUM(E27:E36)=0,"",SUM(E27:E36)) | K37: TOTAL | N37: =IF(SUM(N27:N36)=0,"",SUM(N27:N36)) -> 2808.0475
B39: UTILITY AND PREP. COST | K39: UTILITY AND PREP. COST
B40: Name | E40: Total Cost | K40: Name | N40: Total Cost
B41: Shorenting Oil | C41: ='UTL COST'!$B$3 -> 369000 | D41: ='UTL COST'!$C$3 -> 0.0075 | E41: ='UTL COST'!$D$3 -> 2767.5 | K41: Shorenting Oil | L41: ='UTL COST'!$B$3 -> 369000 | M41: ='UTL COST'!$C$3 -> 0.0075 | N41: ='UTL COST'!$D$3 -> 2767.5
B42: Gas | C42: ='UTL COST'!$B$4 -> #REF! | D42: ='UTL COST'!$C$4 -> 7000 | E42: ='UTL COST'!$D$4 -> #REF! | K42: Gas | L42: ='UTL COST'!$B$4 -> #REF! | M42: ='UTL COST'!$C$4 -> 7000 | N42: ='UTL COST'!$D$4 -> #REF!
B43: Electricity | C43: ='UTL COST'!$B$5 -> #REF! | D43: ='UTL COST'!$C$5 -> 45000 | E43: ='UTL COST'!$D$5 -> #REF! | K43: Electricity | L43: ='UTL COST'!$B$5 -> #REF! | M43: ='UTL COST'!$C$5 -> 45000 | N43: ='UTL COST'!$D$5 -> #REF!
B44: Water | C44: ='UTL COST'!$B$6 -> #REF! | D44: ='UTL COST'!$C$6 -> 525 | E44: 0.1 | K44: Water | L44: ='UTL COST'!$B$6 -> #REF! | M44: ='UTL COST'!$C$6 -> 525 | N44: 0.1
B45: TOTAL | E45: =IF(SUM(E41:E44)=0,"",SUM(E41:E44)) -> #REF! | K45: TOTAL | N45: =IF(SUM(N41:N44)=0,"",SUM(N41:N44)) -> #REF!
B50: DISH NAME | C50: Baked Potato | K50: DISH NAME | L50: Cheese Garlic
B52: EST. SALE PPRICE | C52: 53000 | K52: EST. SALE PPRICE | L52: 82000
B54: TOTAL COST | C54: =IF(SUM(E66,E81,E89)=0,"",SUM(E66,E81,E89)) -> #REF! | K54: TOTAL COST | L54: =IF(SUM(N66,N81,N89)=0,"",SUM(N66,N81,N89)) -> #REF!
B56: COST MARGIN | C56: =IF(C54="","",IF(ISBLANK(C52),"",C54/C52)) -> #REF! | K56: COST MARGIN | L56: =IF(L54="","",IF(ISBLANK(L52),"",L54/L52)) -> #REF!
B58: NET PROFIT | C58: =C52-C54 -> #REF! | K58: NET PROFIT | L58: =L52-L54 -> #REF!
B61: PRIMARY INGREDIENTS | K61: PRIMARY INGREDIENTS
B62: Product Name | C62: Qty. | D62: Cost (per unit) | E62: Total Cost | K62: Product Name | L62: Qty. | M62: Cost (per unit) | N62: Total Cost
B63: Potato | C63: 0.4 | D63: ='F&B'!$F$281 -> 5400 | E63: =IF(OR(ISBLANK(C63),ISBLANK(D63)),"",D63*C63) -> 2160 | K63: Mozzarella Cheese | L63: 0.06 | M63: ='F&B'!$F$99/12 -> 63000 | N63: =IF(OR(ISBLANK(L63),ISBLANK(M63)),"",M63*L63) -> 3780
K64: Garlic Butter | L64: 0.08 | M64: =SAUCES!D107 -> 13438.658 | N64: =IF(OR(ISBLANK(L64),ISBLANK(M64)),"",M64*L64) -> 1075.0927
...

Sheet MAINS
A1: MAINS FOOD COST
B6: DISH NAME | C6: Escalope | K6: DISH NAME | L6: Grilled Chicken
B8: EST. SALE PPRICE | C8: 205000 | K8: EST. SALE PPRICE | L8: 245000
B10: TOTAL COST | C10: =IF(SUM(E22,E37,E45)=0,"",SUM(E22,E37,E45)) -> #REF! | K10: TOTAL COST | L10: =IF(SUM(N22,N37,N45)=0,"",SUM(N22,N37,N45)) -> #REF! | N10: =L10/90000 -> #REF!
B12: COST MARGIN | C12: =IF(C10="","",IF(ISBLANK(C8),"",C10/C8)) -> #REF! | K12: COST MARGIN | L12: =IF(L10="","",IF(ISBLANK(L8),"",L10/L8)) -> #REF!
B14: NET PROFIT | C14: =C8-C10 -> #REF! | K14: NET PROFIT | L14: =L8-L10 -> #REF!
B17: PRIMARY INGREDIENTS | K17: PRIMARY INGREDIENTS
B18: Product Name | C18: Qty. | D18: Cost (per unit) | E18: Total Cost | K18: Product Name | L18: Qty. | M18: Cost (per unit) | N18: Total Cost
B19: Grilled Chicken | C19: 0.28 | D19: =SANDWICHES!$D$19 -> 81000 | E19: =IF(OR(ISBLANK(C19),ISBLANK(D19)),"",D19*C19) -> 22680 | H19: =E19/90000 -> 0.252 | K19: Grilled Chicken | L19: 0.28 | M19: =SANDWICHES!$D$19 -> 81000 | N19: =IF(OR(ISBLANK(L19),ISBLANK(M19)),"",M19*L19) -> 22680
B20: French Fries | C20: 0.16 | D20: =STARTERS!$D$19 -> 19665 | E20: =IF(OR(ISBLANK(C20),ISBLANK(D20)),"",D20*C20) -> 3146.4 | K20: French Fries | L20: 0.2 | M20: =STARTERS!$D$19 -> 19665 | N20: =IF(OR(ISBLANK(L20),ISBLANK(M20)),"",M20*L20) -> 3933
B22: TOTAL | E22: =IF(SUM(E19:E21)=0,"",SUM(E19:E21)) -> 25826.4 | K22: TOTAL | N22: =IF(SUM(N19:N21)=0,"",SUM(N19:N21)) -> 26613
B24: SECONDARY INGREDIENTS | K24: SECONDARY INGREDIENTS
B25: Product Name | C25: Qty | D25: Cost | E25: Total Cost | K25: Product Name | L25: Qty | M25: Cost | N25: Total Cost
B27: Coleslaw | C27: 1 | D27: =SAUCES!$L$58 -> 923.2488 | E27: =D27*C27 -> 923.2488 | K27: Green Salad | L27: 0.3 | M27: =SAUCES!$D$68 -> 3768.1048 | N27: =M27*L27 -> 1130.4314
B28: Garnish | C28: 1 | D28: =SAUCES!$L$44 | E28: =D28*C28 -> 0 | N28: =M28*L28 -> 0
B29: Breaded | C29: 0.5 | D29: =SAUCES!$D$48 -> 563.76 | E29: =D29*C29 -> 281.88 | N29: =M29*L29 -> 0
B30: Pickles | C30: 0.02 | D30: ='F&B'!$F$49/10 -> 13500 | E30: =D30*C30 -> 270 | N30: =M30*L30 -> 0
E31: =D31*C31 -> 0 | N31: =M31*L31 -> 0
E32: =D32*C32 -> 0 | N32: =M32*L32 -> 0
E33: =D33*C33 -> 0 | N33: =M33*L33 -> 0
E34: =D34*C34 -> 0 | N34: =M34*L34 -> 0
E35: =D35*C35 -> 0 | N35: =M35*L35 -> 0
E36: =D36*C36 -> 0 | N36: =M36*L36 -> 0
B37: TOTAL | E37: =IF(SUM(E27:E36)=0,"",SUM(E27:E36)) -> 1475.1288 | K37: TOTAL | N37: =IF(SUM(N27:N36)=0,"",SUM(N27:N36)) -> 1130.4314
B39: UTILITY AND PREP. COST | K39: UTILITY AND PREP. COST
B40: Name | E40: Total Cost | K40: Name | N40: Total Cost
B41: Shorenting Oil | C41: ='UTL COST'!$B$3 -> 369000 | D41: ='UTL COST'!$C$3 -> 0.0075 | E41: ='UTL COST'!$D$3 -> 2767.5 | K41: Shorenting Oil | L41: ='UTL COST'!$B$3 -> 369000 | M41: ='UTL COST'!$C$3 -> 0.0075 | N41: =E41 -> 2767.5
B42: Gas | C42: ='UTL COST'!$B$4 -> #REF! | D42: ='UTL COST'!$C$4 -> 7000 | E42: ='UTL COST'!$D$4 -> #REF! | K42: Gas | L42: ='UTL COST'!$B$4 -> #REF! | M42: ='UTL COST'!$C$4 -> 7000 | N42: ='UTL COST'!$D$4 -> #REF!
B43: Electricity | C43: ='UTL COST'!$B$5 -> #REF! | D43: ='UTL COST'!$C$5 -> 45000 | E43: ='UTL COST'!$D$5 -> #REF! | K43: Electricity | L43: ='UTL COST'!$B$5 -> #REF! | M43: ='UTL COST'!$C$5 -> 45000 | N43: ='UTL COST'!$D$5 -> #REF!
B44: Water | C44: ='UTL COST'!$B$6 -> #REF! | D44: ='UTL COST'!$C$6 -> 525 | E44: 0.1 | K44: Water | L44: ='UTL COST'!$B$6 -> #REF! | M44: ='UTL COST'!$C$6 -> 525 | N44: 0.1
B45: TOTAL | E45: =IF(SUM(E41:E44)=0,"",SUM(E41:E44)) -> #REF! | K45: TOTAL | N45: =IF(SUM(N41:N44)=0,"",SUM(N41:N44)) -> #REF!
B50: DISH NAME | C50: Taouk | K50: DISH NAME | L50: Grilled Chicken Mushrooms
B52: EST. SALE PPRICE | C52: 190000 | K52: EST. SALE PPRICE | L52: 220000
B54: TOTAL COST | C54: =IF(SUM(E66,E81,E89)=0,"",SUM(E66,E81,E89)) -> #REF! | K54: TOTAL COST | L54: =IF(SUM(N66,N81,N89)=0,"",SUM(N66,N81,N89)) -> #REF!
B56: COST MARGIN | C56: =IF(C54="","",IF(ISBLANK(C52),"",C54/C52)) -> #REF! | K56: COST MARGIN | L56: =IF(L54="","",IF(ISBLANK(L52),"",L54/L52)) -> #REF!
B58: NET PROFIT | C58: =C52-C54 -> #REF! | K58: NET PROFIT | L58: =L52-L54 -> #REF!
B61: PRIMARY INGREDIENTS | K61: PRIMARY INGREDIENTS
B62: Product Name | C62: Qty. | D62: Cost (per unit) | E62: Total Cost | K62: Product Name | L62: Qty. | M62: Cost (per unit) | N62: Total Cost
B63: Grilled Chicken | C63: 0.3 | D63: =SANDWICHES!$D$19 -> 81000 | E63: =IF(OR(ISBLANK(C63),ISBLANK(D63)),"",D63*C63) -> 24300 | K63: Grilled Chicken | L63: 0.3 | M63: =SANDWICHES!$D$19 -> 81000 | N63: =IF(OR(ISBLANK(L63),ISBLANK(M63)),"",M63*L63) -> 24300 | O63: =N63/$L$54 -> #REF!
B64: French Fries | C64: 0.2 | D64: =STARTERS!$D$19 -> 19665 | E64: =IF(OR(ISBLANK(C64),ISBLANK(D64)),"",D64*C64) -> 3933 | K64: French Fries | L64: 0.2 | M64: =STARTERS!$D$19 -> 19665 | N64: =IF(OR(ISBLANK(L64),ISBLANK(M64)),"",M64*L64) -> 3933 | O64: =N64/$L$54 -> #REF!
...

Sheet Ramadan
A1: FOUL & HOMMOS FOOD COST
B6: DISH NAME | C6: Foul | K6: DISH NAME | L6: Veggie Plate
B8: EST. SALE PPRICE | C8: =C10/90000 -> #REF! | K8: EST. SALE PPRICE | L8: =L10/90000 -> 0.086407143
B10: TOTAL COST | C10: =IF(SUM(E22,E37,E45)=0,"",SUM(E22,E37,E45)) -> #REF! | E10: =C10/90000 -> #REF! | K10: TOTAL COST | L10: =IF(SUM(N22,N37,N45)=0,"",SUM(N22,N37,N45)) -> 7776.6429
B12: COST MARGIN | C12: =IF(C10="","",IF(ISBLANK(C8),"",C10/C8)) -> #REF! | K12: COST MARGIN | L12: =IF(L10="","",IF(ISBLANK(L8),"",L10/L8)) -> 90000
B14: NET PROFIT | C14: =C8-C10 -> #REF! | K14: NET PROFIT | L14: =L8-L10 -> -7776.5565
B17: PRIMARY INGREDIENTS | K17: PRIMARY INGREDIENTS
B18: Product Name | C18: Qty. | D18: Cost (per unit) | E18: Total Cost | K18: Product Name | L18: Qty. | M18: Cost (per unit) | N18: Total Cost
B19: Foul and Hommos | C19: 1 | D19: ='F&B'!F63 -> 8910 | E19: =IF(OR(ISBLANK(C19),ISBLANK(D19)),"",D19*C19) -> 8910 | K19: Olives | L19: 0.04 | M19: ='F&B'!F45 -> 36000 | N19: =IF(OR(ISBLANK(L19),ISBLANK(M19)),"",M19*L19) -> 1440
B20: Garlic | C20: 0.01 | D20: ='F&B'!F292 -> 19800 | E20: =IF(OR(ISBLANK(C20),ISBLANK(D20)),"",D20*C20) -> 198 | K20: Cucumber | L20: 0.1 | M20: ='F&B'!F284 -> 7200 | N20: =IF(OR(ISBLANK(L20),ISBLANK(M20)),"",M20*L20) -> 720
B21: Lemon Juice | C21: 0.05 | D21: ='F&B'!F287 -> 8100 | E21: =IF(OR(ISBLANK(C21),ISBLANK(D21)),"",D21*C21) -> 405 | K21: Tomatoes | L21: 0.16 | M21: ='F&B'!F279 -> 7200 | N21: =IF(OR(ISBLANK(L21),ISBLANK(M21)),"",M21*L21) -> 1152
B22: TOTAL | E22: =IF(SUM(E19:E21)=0,"",SUM(E19:E21)) -> 9513 | K22: TOTAL | N22: =IF(SUM(N19:N21)=0,"",SUM(N19:N21)) -> 3312
B24: SECONDARY INGREDIENTS | K24: SECONDARY INGREDIENTS
B25: Product Name | C25: Qty | D25: Cost | E25: Total Cost | K25: Product Name | L25: Qty | M25: Cost | N25: Total Cost
B27: Olive Oil | C27: 0.025 | D27: ='F&B'!F43/13 -> 38076.923 | E27: =D27*C27 -> 951.92308 | K27: Mint | L27: 0.5 | M27: ='F&B'!F315 -> 2970 | N27: =M27*L27 -> 1485
B28: Veggie Plate | C28: 1 | D28: =L10 -> 7776.6429 | E28: =D28*C28 -> 7776.6429 | K28: Pickles | L28: 0.045 | M28: ='F&B'!F49/10 -> 13500 | N28: =M28*L28 -> 607.5
E29: =D29*C29 -> 0 | K29: Bread | L29: 1 | M29: ='F&B'!F4/7 -> 1247.1429 | N29: =M29*L29 -> 1247.1429
E30: =D30*C30 -> 0 | K30: Raddish | L30: 0.25 | M30: ='F&B'!F317 -> 4500 | N30: =M30*L30 -> 1125
E31: =D31*C31 -> 0 | N31: =M31*L31 -> 0
E32: =D32*C32 -> 0 | N32: =M32*L32 -> 0
E33: =D33*C33 -> 0 | N33: =M33*L33 -> 0
E34: =D34*C34 -> 0 | N34: =M34*L34 -> 0
E35: =D35*C35 -> 0 | N35: =M35*L35 -> 0
E36: =D36*C36 -> 0 | N36: =M36*L36 -> 0
B37: TOTAL | E37: =IF(SUM(E27:E36)=0,"",SUM(E27:E36)) -> 8728.5659 | K37: TOTAL | N37: =IF(SUM(N27:N36)=0,"",SUM(N27:N36)) -> 4464.6429
B39: UTILITY AND PREP. COST | K39: UTILITY AND PREP. COST
B40: Name | E40: Total Cost | K40: Name | N40: Total Cost
B41: Shorenting Oil | C41: ='UTL COST'!$B$3 -> 369000 | D41: ='UTL COST'!$C$3 -> 0.0075 | E41: 0 | K41: Shorenting Oil | L41: ='UTL COST'!$B$3 -> 369000 | M41: ='UTL COST'!$C$3 -> 0.0075 | N41: 0
B42: Gas | C42: ='UTL COST'!$B$4 -> #REF! | D42: ='UTL COST'!$C$4 -> 7000 | E42: ='UTL COST'!$D$4 -> #REF! | K42: Gas | L42: ='UTL COST'!$B$4 -> #REF! | M42: ='UTL COST'!$C$4 -> 7000 | N42: 0
B43: Electricity | C43: ='UTL COST'!$B$5 -> #REF! | D43: ='UTL COST'!$C$5 -> 45000 | E43: ='UTL COST'!$D$5 -> #REF! | K43: Electricity | L43: ='UTL COST'!$B$5 -> #REF! | M43: ='UTL COST'!$C$5 -> 45000 | N43: ='UTL COST'!$D$5 -> #REF!
B44: Water | C44: ='UTL COST'!$B$6 -> #REF! | D44: ='UTL COST'!$C$6 -> 525 | E44: 0.1 | K44: Water | L44: ='UTL COST'!$B$6 -> #REF! | M44: ='UTL COST'!$C$6 -> 525 | N44: 0.1
B45: TOTAL | E45: =SUM(E41:E44) -> #REF! | K45: TOTAL | N45: 0
B50: DISH NAME | C50: Fateh bi Laban | K50: DISH NAME | L50: Balila
B52: EST. SALE PPRICE | C52: =C54/90000 -> #REF! | K52: EST. SALE PPRICE | L52: =L54/90000 -> #REF!
B54: TOTAL COST | C54: =IF(SUM(E66,E81,E89)=0,"",SUM(E66,E81,E89)) -> #REF! | E54: =C54/90000 -> #REF! | K54: TOTAL COST | L54: =IF(SUM(N66,N81,N89)=0,"",SUM(N66,N81,N89)) -> #REF!
